TEST 1 BEGIN
$ python3 -c "from maze import *; Maze('incorrect_input_1.txt')"
Traceback (most recent call last):
  File "/tmp_amd/ravel/export/ravel/1/rhamadi/abc/a2marking/submissions/5235242/maze.py", line 57, in __init__
    file = open(self.filename)
FileNotFoundError: [Errno 2] No such file or directory: 'some_filename'

During handling of the above exception, another exception occurred:

Traceback (most recent call last):
  File "<string>", line 1, in <module>
  File "/tmp_amd/ravel/export/ravel/1/rhamadi/abc/a2marking/submissions/5235242/maze.py", line 147, in <module>
    maze = Maze('some_filename')
  File "/tmp_amd/ravel/export/ravel/1/rhamadi/abc/a2marking/submissions/5235242/maze.py", line 60, in __init__
    raise MazeError('Incorrect input.')
maze.MazeError: Incorrect input.
TEST 1 END

TEST 2 BEGIN
$ python3 -c "from maze import *; Maze('incorrect_input_2.txt')"
Traceback (most recent call last):
  File "/tmp_amd/ravel/export/ravel/1/rhamadi/abc/a2marking/submissions/5235242/maze.py", line 57, in __init__
    file = open(self.filename)
FileNotFoundError: [Errno 2] No such file or directory: 'some_filename'

During handling of the above exception, another exception occurred:

Traceback (most recent call last):
  File "<string>", line 1, in <module>
  File "/tmp_amd/ravel/export/ravel/1/rhamadi/abc/a2marking/submissions/5235242/maze.py", line 147, in <module>
    maze = Maze('some_filename')
  File "/tmp_amd/ravel/export/ravel/1/rhamadi/abc/a2marking/submissions/5235242/maze.py", line 60, in __init__
    raise MazeError('Incorrect input.')
maze.MazeError: Incorrect input.
TEST 2 END

TEST 3 BEGIN
$ python3 -c "from maze import *; Maze('incorrect_input_3.txt')"
Traceback (most recent call last):
  File "/tmp_amd/ravel/export/ravel/1/rhamadi/abc/a2marking/submissions/5235242/maze.py", line 57, in __init__
    file = open(self.filename)
FileNotFoundError: [Errno 2] No such file or directory: 'some_filename'

During handling of the above exception, another exception occurred:

Traceback (most recent call last):
  File "<string>", line 1, in <module>
  File "/tmp_amd/ravel/export/ravel/1/rhamadi/abc/a2marking/submissions/5235242/maze.py", line 147, in <module>
    maze = Maze('some_filename')
  File "/tmp_amd/ravel/export/ravel/1/rhamadi/abc/a2marking/submissions/5235242/maze.py", line 60, in __init__
    raise MazeError('Incorrect input.')
maze.MazeError: Incorrect input.
TEST 3 END

TEST 4 BEGIN
$ python3 -c "from maze import *; Maze('incorrect_input_4.txt')"
Traceback (most recent call last):
  File "/tmp_amd/ravel/export/ravel/1/rhamadi/abc/a2marking/submissions/5235242/maze.py", line 57, in __init__
    file = open(self.filename)
FileNotFoundError: [Errno 2] No such file or directory: 'some_filename'

During handling of the above exception, another exception occurred:

Traceback (most recent call last):
  File "<string>", line 1, in <module>
  File "/tmp_amd/ravel/export/ravel/1/rhamadi/abc/a2marking/submissions/5235242/maze.py", line 147, in <module>
    maze = Maze('some_filename')
  File "/tmp_amd/ravel/export/ravel/1/rhamadi/abc/a2marking/submissions/5235242/maze.py", line 60, in __init__
    raise MazeError('Incorrect input.')
maze.MazeError: Incorrect input.
TEST 4 END

TEST 5 BEGIN
$ python3 -c "from maze import *; Maze('incorrect_input_5.txt')"
Traceback (most recent call last):
  File "/tmp_amd/ravel/export/ravel/1/rhamadi/abc/a2marking/submissions/5235242/maze.py", line 57, in __init__
    file = open(self.filename)
FileNotFoundError: [Errno 2] No such file or directory: 'some_filename'

During handling of the above exception, another exception occurred:

Traceback (most recent call last):
  File "<string>", line 1, in <module>
  File "/tmp_amd/ravel/export/ravel/1/rhamadi/abc/a2marking/submissions/5235242/maze.py", line 147, in <module>
    maze = Maze('some_filename')
  File "/tmp_amd/ravel/export/ravel/1/rhamadi/abc/a2marking/submissions/5235242/maze.py", line 60, in __init__
    raise MazeError('Incorrect input.')
maze.MazeError: Incorrect input.
TEST 5 END

TEST 6 BEGIN
$ python3 -c "from maze import *; Maze('incorrect_input_6.txt')"
Traceback (most recent call last):
  File "/tmp_amd/ravel/export/ravel/1/rhamadi/abc/a2marking/submissions/5235242/maze.py", line 57, in __init__
    file = open(self.filename)
FileNotFoundError: [Errno 2] No such file or directory: 'some_filename'

During handling of the above exception, another exception occurred:

Traceback (most recent call last):
  File "<string>", line 1, in <module>
  File "/tmp_amd/ravel/export/ravel/1/rhamadi/abc/a2marking/submissions/5235242/maze.py", line 147, in <module>
    maze = Maze('some_filename')
  File "/tmp_amd/ravel/export/ravel/1/rhamadi/abc/a2marking/submissions/5235242/maze.py", line 60, in __init__
    raise MazeError('Incorrect input.')
maze.MazeError: Incorrect input.
TEST 6 END

TEST 7 BEGIN
$ python3 -c "from maze import *; Maze('not_a_maze_1.txt')"
Traceback (most recent call last):
  File "/tmp_amd/ravel/export/ravel/1/rhamadi/abc/a2marking/submissions/5235242/maze.py", line 57, in __init__
    file = open(self.filename)
FileNotFoundError: [Errno 2] No such file or directory: 'some_filename'

During handling of the above exception, another exception occurred:

Traceback (most recent call last):
  File "<string>", line 1, in <module>
  File "/tmp_amd/ravel/export/ravel/1/rhamadi/abc/a2marking/submissions/5235242/maze.py", line 147, in <module>
    maze = Maze('some_filename')
  File "/tmp_amd/ravel/export/ravel/1/rhamadi/abc/a2marking/submissions/5235242/maze.py", line 60, in __init__
    raise MazeError('Incorrect input.')
maze.MazeError: Incorrect input.
TEST 7 END

TEST 8 BEGIN
$ python3 -c "from maze import *; Maze('not_a_maze_2.txt')"
Traceback (most recent call last):
  File "/tmp_amd/ravel/export/ravel/1/rhamadi/abc/a2marking/submissions/5235242/maze.py", line 57, in __init__
    file = open(self.filename)
FileNotFoundError: [Errno 2] No such file or directory: 'some_filename'

During handling of the above exception, another exception occurred:

Traceback (most recent call last):
  File "<string>", line 1, in <module>
  File "/tmp_amd/ravel/export/ravel/1/rhamadi/abc/a2marking/submissions/5235242/maze.py", line 147, in <module>
    maze = Maze('some_filename')
  File "/tmp_amd/ravel/export/ravel/1/rhamadi/abc/a2marking/submissions/5235242/maze.py", line 60, in __init__
    raise MazeError('Incorrect input.')
maze.MazeError: Incorrect input.
TEST 8 END

TEST 9 BEGIN
$ python3 -c "from maze import *; Maze('not_a_maze_3.txt')"
Traceback (most recent call last):
  File "/tmp_amd/ravel/export/ravel/1/rhamadi/abc/a2marking/submissions/5235242/maze.py", line 57, in __init__
    file = open(self.filename)
FileNotFoundError: [Errno 2] No such file or directory: 'some_filename'

During handling of the above exception, another exception occurred:

Traceback (most recent call last):
  File "<string>", line 1, in <module>
  File "/tmp_amd/ravel/export/ravel/1/rhamadi/abc/a2marking/submissions/5235242/maze.py", line 147, in <module>
    maze = Maze('some_filename')
  File "/tmp_amd/ravel/export/ravel/1/rhamadi/abc/a2marking/submissions/5235242/maze.py", line 60, in __init__
    raise MazeError('Incorrect input.')
maze.MazeError: Incorrect input.
TEST 9 END

TEST 10 BEGIN
$ python3 -c "from maze import *; Maze('not_a_maze_4.txt')"
Traceback (most recent call last):
  File "/tmp_amd/ravel/export/ravel/1/rhamadi/abc/a2marking/submissions/5235242/maze.py", line 57, in __init__
    file = open(self.filename)
FileNotFoundError: [Errno 2] No such file or directory: 'some_filename'

During handling of the above exception, another exception occurred:

Traceback (most recent call last):
  File "<string>", line 1, in <module>
  File "/tmp_amd/ravel/export/ravel/1/rhamadi/abc/a2marking/submissions/5235242/maze.py", line 147, in <module>
    maze = Maze('some_filename')
  File "/tmp_amd/ravel/export/ravel/1/rhamadi/abc/a2marking/submissions/5235242/maze.py", line 60, in __init__
    raise MazeError('Incorrect input.')
maze.MazeError: Incorrect input.
TEST 10 END

TEST 11 BEGIN
$ python3 -c "from maze import *; maze = Maze('maze_3.txt'); maze.analyse()"
Traceback (most recent call last):
  File "/tmp_amd/ravel/export/ravel/1/rhamadi/abc/a2marking/submissions/5235242/maze.py", line 57, in __init__
    file = open(self.filename)
FileNotFoundError: [Errno 2] No such file or directory: 'some_filename'

During handling of the above exception, another exception occurred:

Traceback (most recent call last):
  File "<string>", line 1, in <module>
  File "/tmp_amd/ravel/export/ravel/1/rhamadi/abc/a2marking/submissions/5235242/maze.py", line 147, in <module>
    maze = Maze('some_filename')
  File "/tmp_amd/ravel/export/ravel/1/rhamadi/abc/a2marking/submissions/5235242/maze.py", line 60, in __init__
    raise MazeError('Incorrect input.')
maze.MazeError: Incorrect input.
TEST 11 END

TEST 12 BEGIN
$ python3 -c "from maze import *; maze = Maze('maze_4.txt'); maze.analyse()"
Traceback (most recent call last):
  File "/tmp_amd/ravel/export/ravel/1/rhamadi/abc/a2marking/submissions/5235242/maze.py", line 57, in __init__
    file = open(self.filename)
FileNotFoundError: [Errno 2] No such file or directory: 'some_filename'

During handling of the above exception, another exception occurred:

Traceback (most recent call last):
  File "<string>", line 1, in <module>
  File "/tmp_amd/ravel/export/ravel/1/rhamadi/abc/a2marking/submissions/5235242/maze.py", line 147, in <module>
    maze = Maze('some_filename')
  File "/tmp_amd/ravel/export/ravel/1/rhamadi/abc/a2marking/submissions/5235242/maze.py", line 60, in __init__
    raise MazeError('Incorrect input.')
maze.MazeError: Incorrect input.
TEST 12 END

TEST 13 BEGIN
$ python3 -c "from maze import *; maze = Maze('maze_5.txt'); maze.analyse()"
Traceback (most recent call last):
  File "/tmp_amd/ravel/export/ravel/1/rhamadi/abc/a2marking/submissions/5235242/maze.py", line 57, in __init__
    file = open(self.filename)
FileNotFoundError: [Errno 2] No such file or directory: 'some_filename'

During handling of the above exception, another exception occurred:

Traceback (most recent call last):
  File "<string>", line 1, in <module>
  File "/tmp_amd/ravel/export/ravel/1/rhamadi/abc/a2marking/submissions/5235242/maze.py", line 147, in <module>
    maze = Maze('some_filename')
  File "/tmp_amd/ravel/export/ravel/1/rhamadi/abc/a2marking/submissions/5235242/maze.py", line 60, in __init__
    raise MazeError('Incorrect input.')
maze.MazeError: Incorrect input.
TEST 13 END

TEST 14 BEGIN
$ python3 -c "from maze import *; maze = Maze('maze_6.txt'); maze.analyse()"
Traceback (most recent call last):
  File "/tmp_amd/ravel/export/ravel/1/rhamadi/abc/a2marking/submissions/5235242/maze.py", line 57, in __init__
    file = open(self.filename)
FileNotFoundError: [Errno 2] No such file or directory: 'some_filename'

During handling of the above exception, another exception occurred:

Traceback (most recent call last):
  File "<string>", line 1, in <module>
  File "/tmp_amd/ravel/export/ravel/1/rhamadi/abc/a2marking/submissions/5235242/maze.py", line 147, in <module>
    maze = Maze('some_filename')
  File "/tmp_amd/ravel/export/ravel/1/rhamadi/abc/a2marking/submissions/5235242/maze.py", line 60, in __init__
    raise MazeError('Incorrect input.')
maze.MazeError: Incorrect input.
TEST 14 END

TEST 15 BEGIN
$ python3 -c "from maze import *; maze = Maze('maze_7.txt'); maze.analyse()"
Traceback (most recent call last):
  File "/tmp_amd/ravel/export/ravel/1/rhamadi/abc/a2marking/submissions/5235242/maze.py", line 57, in __init__
    file = open(self.filename)
FileNotFoundError: [Errno 2] No such file or directory: 'some_filename'

During handling of the above exception, another exception occurred:

Traceback (most recent call last):
  File "<string>", line 1, in <module>
  File "/tmp_amd/ravel/export/ravel/1/rhamadi/abc/a2marking/submissions/5235242/maze.py", line 147, in <module>
    maze = Maze('some_filename')
  File "/tmp_amd/ravel/export/ravel/1/rhamadi/abc/a2marking/submissions/5235242/maze.py", line 60, in __init__
    raise MazeError('Incorrect input.')
maze.MazeError: Incorrect input.
TEST 15 END

TEST 16 BEGIN
$ python3 -c "from maze import *; maze = Maze('maze_8.txt'); maze.analyse()"
Traceback (most recent call last):
  File "/tmp_amd/ravel/export/ravel/1/rhamadi/abc/a2marking/submissions/5235242/maze.py", line 57, in __init__
    file = open(self.filename)
FileNotFoundError: [Errno 2] No such file or directory: 'some_filename'

During handling of the above exception, another exception occurred:

Traceback (most recent call last):
  File "<string>", line 1, in <module>
  File "/tmp_amd/ravel/export/ravel/1/rhamadi/abc/a2marking/submissions/5235242/maze.py", line 147, in <module>
    maze = Maze('some_filename')
  File "/tmp_amd/ravel/export/ravel/1/rhamadi/abc/a2marking/submissions/5235242/maze.py", line 60, in __init__
    raise MazeError('Incorrect input.')
maze.MazeError: Incorrect input.
TEST 16 END

TEST 17 BEGIN
$ python3 -c "from maze import *; maze = Maze('maze_9.txt'); maze.analyse()"
Traceback (most recent call last):
  File "/tmp_amd/ravel/export/ravel/1/rhamadi/abc/a2marking/submissions/5235242/maze.py", line 57, in __init__
    file = open(self.filename)
FileNotFoundError: [Errno 2] No such file or directory: 'some_filename'

During handling of the above exception, another exception occurred:

Traceback (most recent call last):
  File "<string>", line 1, in <module>
  File "/tmp_amd/ravel/export/ravel/1/rhamadi/abc/a2marking/submissions/5235242/maze.py", line 147, in <module>
    maze = Maze('some_filename')
  File "/tmp_amd/ravel/export/ravel/1/rhamadi/abc/a2marking/submissions/5235242/maze.py", line 60, in __init__
    raise MazeError('Incorrect input.')
maze.MazeError: Incorrect input.
TEST 17 END

TEST 18 BEGIN
$ python3 -c "from maze import *; maze = Maze('maze_10.txt'); maze.analyse()"
Traceback (most recent call last):
  File "/tmp_amd/ravel/export/ravel/1/rhamadi/abc/a2marking/submissions/5235242/maze.py", line 57, in __init__
    file = open(self.filename)
FileNotFoundError: [Errno 2] No such file or directory: 'some_filename'

During handling of the above exception, another exception occurred:

Traceback (most recent call last):
  File "<string>", line 1, in <module>
  File "/tmp_amd/ravel/export/ravel/1/rhamadi/abc/a2marking/submissions/5235242/maze.py", line 147, in <module>
    maze = Maze('some_filename')
  File "/tmp_amd/ravel/export/ravel/1/rhamadi/abc/a2marking/submissions/5235242/maze.py", line 60, in __init__
    raise MazeError('Incorrect input.')
maze.MazeError: Incorrect input.
TEST 18 END

TEST 19 BEGIN
$ python3 -c "from maze import *; maze = Maze('maze_11.txt'); maze.analyse()"
Traceback (most recent call last):
  File "/tmp_amd/ravel/export/ravel/1/rhamadi/abc/a2marking/submissions/5235242/maze.py", line 57, in __init__
    file = open(self.filename)
FileNotFoundError: [Errno 2] No such file or directory: 'some_filename'

During handling of the above exception, another exception occurred:

Traceback (most recent call last):
  File "<string>", line 1, in <module>
  File "/tmp_amd/ravel/export/ravel/1/rhamadi/abc/a2marking/submissions/5235242/maze.py", line 147, in <module>
    maze = Maze('some_filename')
  File "/tmp_amd/ravel/export/ravel/1/rhamadi/abc/a2marking/submissions/5235242/maze.py", line 60, in __init__
    raise MazeError('Incorrect input.')
maze.MazeError: Incorrect input.
TEST 19 END

TEST 20 BEGIN
$ python3 -c "from maze import *; maze = Maze('maze_12.txt'); maze.analyse()"
Traceback (most recent call last):
  File "/tmp_amd/ravel/export/ravel/1/rhamadi/abc/a2marking/submissions/5235242/maze.py", line 57, in __init__
    file = open(self.filename)
FileNotFoundError: [Errno 2] No such file or directory: 'some_filename'

During handling of the above exception, another exception occurred:

Traceback (most recent call last):
  File "<string>", line 1, in <module>
  File "/tmp_amd/ravel/export/ravel/1/rhamadi/abc/a2marking/submissions/5235242/maze.py", line 147, in <module>
    maze = Maze('some_filename')
  File "/tmp_amd/ravel/export/ravel/1/rhamadi/abc/a2marking/submissions/5235242/maze.py", line 60, in __init__
    raise MazeError('Incorrect input.')
maze.MazeError: Incorrect input.
TEST 20 END

TEST 21 BEGIN
$ python3 -c "from maze import *; maze = Maze('maze_13.txt'); maze.analyse()"
Traceback (most recent call last):
  File "/tmp_amd/ravel/export/ravel/1/rhamadi/abc/a2marking/submissions/5235242/maze.py", line 57, in __init__
    file = open(self.filename)
FileNotFoundError: [Errno 2] No such file or directory: 'some_filename'

During handling of the above exception, another exception occurred:

Traceback (most recent call last):
  File "<string>", line 1, in <module>
  File "/tmp_amd/ravel/export/ravel/1/rhamadi/abc/a2marking/submissions/5235242/maze.py", line 147, in <module>
    maze = Maze('some_filename')
  File "/tmp_amd/ravel/export/ravel/1/rhamadi/abc/a2marking/submissions/5235242/maze.py", line 60, in __init__
    raise MazeError('Incorrect input.')
maze.MazeError: Incorrect input.
TEST 21 END

TEST 22 BEGIN
$ python3 -c "from maze import *; maze = Maze('labyrinth_2.txt'); maze.analyse()"
Traceback (most recent call last):
  File "/tmp_amd/ravel/export/ravel/1/rhamadi/abc/a2marking/submissions/5235242/maze.py", line 57, in __init__
    file = open(self.filename)
FileNotFoundError: [Errno 2] No such file or directory: 'some_filename'

During handling of the above exception, another exception occurred:

Traceback (most recent call last):
  File "<string>", line 1, in <module>
  File "/tmp_amd/ravel/export/ravel/1/rhamadi/abc/a2marking/submissions/5235242/maze.py", line 147, in <module>
    maze = Maze('some_filename')
  File "/tmp_amd/ravel/export/ravel/1/rhamadi/abc/a2marking/submissions/5235242/maze.py", line 60, in __init__
    raise MazeError('Incorrect input.')
maze.MazeError: Incorrect input.
TEST 22 END

TEST 23 BEGIN
$ python3 -c "from maze import *; maze = Maze('labyrinth_3.txt'); maze.analyse()"
Traceback (most recent call last):
  File "/tmp_amd/ravel/export/ravel/1/rhamadi/abc/a2marking/submissions/5235242/maze.py", line 57, in __init__
    file = open(self.filename)
FileNotFoundError: [Errno 2] No such file or directory: 'some_filename'

During handling of the above exception, another exception occurred:

Traceback (most recent call last):
  File "<string>", line 1, in <module>
  File "/tmp_amd/ravel/export/ravel/1/rhamadi/abc/a2marking/submissions/5235242/maze.py", line 147, in <module>
    maze = Maze('some_filename')
  File "/tmp_amd/ravel/export/ravel/1/rhamadi/abc/a2marking/submissions/5235242/maze.py", line 60, in __init__
    raise MazeError('Incorrect input.')
maze.MazeError: Incorrect input.
TEST 23 END

TEST 24 BEGIN
$ python3 -c "from maze import *; maze = Maze('labyrinth_4.txt'); maze.analyse()"
Traceback (most recent call last):
  File "/tmp_amd/ravel/export/ravel/1/rhamadi/abc/a2marking/submissions/5235242/maze.py", line 57, in __init__
    file = open(self.filename)
FileNotFoundError: [Errno 2] No such file or directory: 'some_filename'

During handling of the above exception, another exception occurred:

Traceback (most recent call last):
  File "<string>", line 1, in <module>
  File "/tmp_amd/ravel/export/ravel/1/rhamadi/abc/a2marking/submissions/5235242/maze.py", line 147, in <module>
    maze = Maze('some_filename')
  File "/tmp_amd/ravel/export/ravel/1/rhamadi/abc/a2marking/submissions/5235242/maze.py", line 60, in __init__
    raise MazeError('Incorrect input.')
maze.MazeError: Incorrect input.
TEST 24 END

TEST 25 BEGIN
$ python3 -c "from maze import *; maze = Maze('labyrinth_5.txt'); maze.analyse()"
Traceback (most recent call last):
  File "/tmp_amd/ravel/export/ravel/1/rhamadi/abc/a2marking/submissions/5235242/maze.py", line 57, in __init__
    file = open(self.filename)
FileNotFoundError: [Errno 2] No such file or directory: 'some_filename'

During handling of the above exception, another exception occurred:

Traceback (most recent call last):
  File "<string>", line 1, in <module>
  File "/tmp_amd/ravel/export/ravel/1/rhamadi/abc/a2marking/submissions/5235242/maze.py", line 147, in <module>
    maze = Maze('some_filename')
  File "/tmp_amd/ravel/export/ravel/1/rhamadi/abc/a2marking/submissions/5235242/maze.py", line 60, in __init__
    raise MazeError('Incorrect input.')
maze.MazeError: Incorrect input.
TEST 25 END

TEST 26 BEGIN
$ python3 -c "from maze import *; maze = Maze('maze_3.txt'); maze.display()"
Traceback (most recent call last):
  File "/tmp_amd/ravel/export/ravel/1/rhamadi/abc/a2marking/submissions/5235242/maze.py", line 57, in __init__
    file = open(self.filename)
FileNotFoundError: [Errno 2] No such file or directory: 'some_filename'

During handling of the above exception, another exception occurred:

Traceback (most recent call last):
  File "<string>", line 1, in <module>
  File "/tmp_amd/ravel/export/ravel/1/rhamadi/abc/a2marking/submissions/5235242/maze.py", line 147, in <module>
    maze = Maze('some_filename')
  File "/tmp_amd/ravel/export/ravel/1/rhamadi/abc/a2marking/submissions/5235242/maze.py", line 60, in __init__
    raise MazeError('Incorrect input.')
maze.MazeError: Incorrect input.
TEST 26 END

TEST 27 BEGIN
$ python3 -c "from maze import *; maze = Maze('maze_4.txt'); maze.display()"
Traceback (most recent call last):
  File "/tmp_amd/ravel/export/ravel/1/rhamadi/abc/a2marking/submissions/5235242/maze.py", line 57, in __init__
    file = open(self.filename)
FileNotFoundError: [Errno 2] No such file or directory: 'some_filename'

During handling of the above exception, another exception occurred:

Traceback (most recent call last):
  File "<string>", line 1, in <module>
  File "/tmp_amd/ravel/export/ravel/1/rhamadi/abc/a2marking/submissions/5235242/maze.py", line 147, in <module>
    maze = Maze('some_filename')
  File "/tmp_amd/ravel/export/ravel/1/rhamadi/abc/a2marking/submissions/5235242/maze.py", line 60, in __init__
    raise MazeError('Incorrect input.')
maze.MazeError: Incorrect input.
TEST 27 END

TEST 28 BEGIN
$ python3 -c "from maze import *; maze = Maze('maze_5.txt'); maze.display()"
Traceback (most recent call last):
  File "/tmp_amd/ravel/export/ravel/1/rhamadi/abc/a2marking/submissions/5235242/maze.py", line 57, in __init__
    file = open(self.filename)
FileNotFoundError: [Errno 2] No such file or directory: 'some_filename'

During handling of the above exception, another exception occurred:

Traceback (most recent call last):
  File "<string>", line 1, in <module>
  File "/tmp_amd/ravel/export/ravel/1/rhamadi/abc/a2marking/submissions/5235242/maze.py", line 147, in <module>
    maze = Maze('some_filename')
  File "/tmp_amd/ravel/export/ravel/1/rhamadi/abc/a2marking/submissions/5235242/maze.py", line 60, in __init__
    raise MazeError('Incorrect input.')
maze.MazeError: Incorrect input.
TEST 28 END

TEST 29 BEGIN
$ python3 -c "from maze import *; maze = Maze('maze_6.txt'); maze.display()"
Traceback (most recent call last):
  File "/tmp_amd/ravel/export/ravel/1/rhamadi/abc/a2marking/submissions/5235242/maze.py", line 57, in __init__
    file = open(self.filename)
FileNotFoundError: [Errno 2] No such file or directory: 'some_filename'

During handling of the above exception, another exception occurred:

Traceback (most recent call last):
  File "<string>", line 1, in <module>
  File "/tmp_amd/ravel/export/ravel/1/rhamadi/abc/a2marking/submissions/5235242/maze.py", line 147, in <module>
    maze = Maze('some_filename')
  File "/tmp_amd/ravel/export/ravel/1/rhamadi/abc/a2marking/submissions/5235242/maze.py", line 60, in __init__
    raise MazeError('Incorrect input.')
maze.MazeError: Incorrect input.
TEST 29 END

TEST 30 BEGIN
$ python3 -c "from maze import *; maze = Maze('maze_7.txt'); maze.display()"
Traceback (most recent call last):
  File "/tmp_amd/ravel/export/ravel/1/rhamadi/abc/a2marking/submissions/5235242/maze.py", line 57, in __init__
    file = open(self.filename)
FileNotFoundError: [Errno 2] No such file or directory: 'some_filename'

During handling of the above exception, another exception occurred:

Traceback (most recent call last):
  File "<string>", line 1, in <module>
  File "/tmp_amd/ravel/export/ravel/1/rhamadi/abc/a2marking/submissions/5235242/maze.py", line 147, in <module>
    maze = Maze('some_filename')
  File "/tmp_amd/ravel/export/ravel/1/rhamadi/abc/a2marking/submissions/5235242/maze.py", line 60, in __init__
    raise MazeError('Incorrect input.')
maze.MazeError: Incorrect input.
TEST 30 END

TEST 31 BEGIN
$ python3 -c "from maze import *; maze = Maze('maze_8.txt'); maze.display()"
Traceback (most recent call last):
  File "/tmp_amd/ravel/export/ravel/1/rhamadi/abc/a2marking/submissions/5235242/maze.py", line 57, in __init__
    file = open(self.filename)
FileNotFoundError: [Errno 2] No such file or directory: 'some_filename'

During handling of the above exception, another exception occurred:

Traceback (most recent call last):
  File "<string>", line 1, in <module>
  File "/tmp_amd/ravel/export/ravel/1/rhamadi/abc/a2marking/submissions/5235242/maze.py", line 147, in <module>
    maze = Maze('some_filename')
  File "/tmp_amd/ravel/export/ravel/1/rhamadi/abc/a2marking/submissions/5235242/maze.py", line 60, in __init__
    raise MazeError('Incorrect input.')
maze.MazeError: Incorrect input.
TEST 31 END

TEST 32 BEGIN
$ python3 -c "from maze import *; maze = Maze('maze_9.txt'); maze.display()"
Traceback (most recent call last):
  File "/tmp_amd/ravel/export/ravel/1/rhamadi/abc/a2marking/submissions/5235242/maze.py", line 57, in __init__
    file = open(self.filename)
FileNotFoundError: [Errno 2] No such file or directory: 'some_filename'

During handling of the above exception, another exception occurred:

Traceback (most recent call last):
  File "<string>", line 1, in <module>
  File "/tmp_amd/ravel/export/ravel/1/rhamadi/abc/a2marking/submissions/5235242/maze.py", line 147, in <module>
    maze = Maze('some_filename')
  File "/tmp_amd/ravel/export/ravel/1/rhamadi/abc/a2marking/submissions/5235242/maze.py", line 60, in __init__
    raise MazeError('Incorrect input.')
maze.MazeError: Incorrect input.
TEST 32 END

TEST 33 BEGIN
$ python3 -c "from maze import *; maze = Maze('maze_10.txt'); maze.display()"
Traceback (most recent call last):
  File "/tmp_amd/ravel/export/ravel/1/rhamadi/abc/a2marking/submissions/5235242/maze.py", line 57, in __init__
    file = open(self.filename)
FileNotFoundError: [Errno 2] No such file or directory: 'some_filename'

During handling of the above exception, another exception occurred:

Traceback (most recent call last):
  File "<string>", line 1, in <module>
  File "/tmp_amd/ravel/export/ravel/1/rhamadi/abc/a2marking/submissions/5235242/maze.py", line 147, in <module>
    maze = Maze('some_filename')
  File "/tmp_amd/ravel/export/ravel/1/rhamadi/abc/a2marking/submissions/5235242/maze.py", line 60, in __init__
    raise MazeError('Incorrect input.')
maze.MazeError: Incorrect input.
TEST 33 END

TEST 34 BEGIN
$ python3 -c "from maze import *; maze = Maze('maze_11.txt'); maze.display()"
Traceback (most recent call last):
  File "/tmp_amd/ravel/export/ravel/1/rhamadi/abc/a2marking/submissions/5235242/maze.py", line 57, in __init__
    file = open(self.filename)
FileNotFoundError: [Errno 2] No such file or directory: 'some_filename'

During handling of the above exception, another exception occurred:

Traceback (most recent call last):
  File "<string>", line 1, in <module>
  File "/tmp_amd/ravel/export/ravel/1/rhamadi/abc/a2marking/submissions/5235242/maze.py", line 147, in <module>
    maze = Maze('some_filename')
  File "/tmp_amd/ravel/export/ravel/1/rhamadi/abc/a2marking/submissions/5235242/maze.py", line 60, in __init__
    raise MazeError('Incorrect input.')
maze.MazeError: Incorrect input.
TEST 34 END

TEST 35 BEGIN
$ python3 -c "from maze import *; maze = Maze('maze_12.txt'); maze.display()"
Traceback (most recent call last):
  File "/tmp_amd/ravel/export/ravel/1/rhamadi/abc/a2marking/submissions/5235242/maze.py", line 57, in __init__
    file = open(self.filename)
FileNotFoundError: [Errno 2] No such file or directory: 'some_filename'

During handling of the above exception, another exception occurred:

Traceback (most recent call last):
  File "<string>", line 1, in <module>
  File "/tmp_amd/ravel/export/ravel/1/rhamadi/abc/a2marking/submissions/5235242/maze.py", line 147, in <module>
    maze = Maze('some_filename')
  File "/tmp_amd/ravel/export/ravel/1/rhamadi/abc/a2marking/submissions/5235242/maze.py", line 60, in __init__
    raise MazeError('Incorrect input.')
maze.MazeError: Incorrect input.
TEST 35 END

TEST 36 BEGIN
$ python3 -c "from maze import *; maze = Maze('maze_13.txt'); maze.display()"
Traceback (most recent call last):
  File "/tmp_amd/ravel/export/ravel/1/rhamadi/abc/a2marking/submissions/5235242/maze.py", line 57, in __init__
    file = open(self.filename)
FileNotFoundError: [Errno 2] No such file or directory: 'some_filename'

During handling of the above exception, another exception occurred:

Traceback (most recent call last):
  File "<string>", line 1, in <module>
  File "/tmp_amd/ravel/export/ravel/1/rhamadi/abc/a2marking/submissions/5235242/maze.py", line 147, in <module>
    maze = Maze('some_filename')
  File "/tmp_amd/ravel/export/ravel/1/rhamadi/abc/a2marking/submissions/5235242/maze.py", line 60, in __init__
    raise MazeError('Incorrect input.')
maze.MazeError: Incorrect input.
TEST 36 END

TEST 37 BEGIN
$ python3 -c "from maze import *; maze = Maze('labyrinth_2.txt'); maze.display()"
Traceback (most recent call last):
  File "/tmp_amd/ravel/export/ravel/1/rhamadi/abc/a2marking/submissions/5235242/maze.py", line 57, in __init__
    file = open(self.filename)
FileNotFoundError: [Errno 2] No such file or directory: 'some_filename'

During handling of the above exception, another exception occurred:

Traceback (most recent call last):
  File "<string>", line 1, in <module>
  File "/tmp_amd/ravel/export/ravel/1/rhamadi/abc/a2marking/submissions/5235242/maze.py", line 147, in <module>
    maze = Maze('some_filename')
  File "/tmp_amd/ravel/export/ravel/1/rhamadi/abc/a2marking/submissions/5235242/maze.py", line 60, in __init__
    raise MazeError('Incorrect input.')
maze.MazeError: Incorrect input.
TEST 37 END

TEST 38 BEGIN
$ python3 -c "from maze import *; maze = Maze('labyrinth_3.txt'); maze.display()"
Traceback (most recent call last):
  File "/tmp_amd/ravel/export/ravel/1/rhamadi/abc/a2marking/submissions/5235242/maze.py", line 57, in __init__
    file = open(self.filename)
FileNotFoundError: [Errno 2] No such file or directory: 'some_filename'

During handling of the above exception, another exception occurred:

Traceback (most recent call last):
  File "<string>", line 1, in <module>
  File "/tmp_amd/ravel/export/ravel/1/rhamadi/abc/a2marking/submissions/5235242/maze.py", line 147, in <module>
    maze = Maze('some_filename')
  File "/tmp_amd/ravel/export/ravel/1/rhamadi/abc/a2marking/submissions/5235242/maze.py", line 60, in __init__
    raise MazeError('Incorrect input.')
maze.MazeError: Incorrect input.
TEST 38 END

TEST 39 BEGIN
$ python3 -c "from maze import *; maze = Maze('labyrinth_4.txt'); maze.display()"
Traceback (most recent call last):
  File "/tmp_amd/ravel/export/ravel/1/rhamadi/abc/a2marking/submissions/5235242/maze.py", line 57, in __init__
    file = open(self.filename)
FileNotFoundError: [Errno 2] No such file or directory: 'some_filename'

During handling of the above exception, another exception occurred:

Traceback (most recent call last):
  File "<string>", line 1, in <module>
  File "/tmp_amd/ravel/export/ravel/1/rhamadi/abc/a2marking/submissions/5235242/maze.py", line 147, in <module>
    maze = Maze('some_filename')
  File "/tmp_amd/ravel/export/ravel/1/rhamadi/abc/a2marking/submissions/5235242/maze.py", line 60, in __init__
    raise MazeError('Incorrect input.')
maze.MazeError: Incorrect input.
TEST 39 END

TEST 40 BEGIN
$ python3 -c "from maze import *; maze = Maze('labyrinth_5.txt'); maze.display()"
Traceback (most recent call last):
  File "/tmp_amd/ravel/export/ravel/1/rhamadi/abc/a2marking/submissions/5235242/maze.py", line 57, in __init__
    file = open(self.filename)
FileNotFoundError: [Errno 2] No such file or directory: 'some_filename'

During handling of the above exception, another exception occurred:

Traceback (most recent call last):
  File "<string>", line 1, in <module>
  File "/tmp_amd/ravel/export/ravel/1/rhamadi/abc/a2marking/submissions/5235242/maze.py", line 147, in <module>
    maze = Maze('some_filename')
  File "/tmp_amd/ravel/export/ravel/1/rhamadi/abc/a2marking/submissions/5235242/maze.py", line 60, in __init__
    raise MazeError('Incorrect input.')
maze.MazeError: Incorrect input.
TEST 40 END

